Script Initialisation Error
Traceback (most recent call last):
  File "C:\Python311\Lib\site-packages\uiautomator2\__init__.py", line 1946, in connect_adb_wifi
    subprocess.call([adbutils.adb_path(), "-s", addr, "wait-for-device"],
  File "C:\Python311\Lib\subprocess.py", line 391, in call
    return p.wait(timeout=timeout)
           ^^^^^^^^^^^^^^^^^^^^^^^
  File "C:\Python311\Lib\subprocess.py", line 1262, in wait
    return self._wait(timeout=timeout)
           ^^^^^^^^^^^^^^^^^^^^^^^^^^^
  File "C:\Python311\Lib\subprocess.py", line 1546, in _wait
    raise TimeoutExpired(self.args, timeout)
subprocess.TimeoutExpired: Command '['C:\\platform-tools\\adb.EXE', '-s', '127.0.0.1:5557', 'wait-for-device']' timed out after 2 seconds

During handling of the above exception, another exception occurred:

Traceback (most recent call last):
  File "c:\Users\mizan\Documents\GitHub\BAAuto\script.py", line 135, in <module>
    if adb.init():
       ^^^^^^^^^^
  File "c:\Users\mizan\Documents\GitHub\BAAuto\util\adb.py", line 17, in init
    return self.start_server()
          ^^^^^^^^^^^^^^^^^^^
  File "c:\Users\mizan\Documents\GitHub\BAAuto\util\adb.py", line 39, in start_server
    Adb.u2device = u2.connect_adb_wifi(Adb.service)
                   ^^^^^^^^^^^^^^^^^^^^^^^^^^^^^^^^
  File "C:\Python311\Lib\site-packages\uiautomator2\__init__.py", line 1949, in connect_adb_wifi
    raise ConnectError("Fail execute", "adb connect " + addr)
uiautomator2.exceptions.ConnectError: ('Fail execute', 'adb connect 127.0.0.1:5557')

